<mujoco model="mini_cheetah">
  <compiler angle="radian" meshdir="./meshes/" autolimits="true" />
  <default />
  <asset>
    <mesh name="torso" file="body.stl" />
    <mesh name="abad" file="abad.stl" />
    <mesh name="thigh" file="thigh.stl" />
    <mesh name="shank" file="shank.stl" />
    <texture type="skybox" builtin="gradient" rgb1=".3 .5 .7" rgb2="0 0 0" width="32" height="512" />
    <texture name="body" type="cube" builtin="flat" mark="cross" width="127" height="1278" rgb1="0.8 0.6 0.4" rgb2="0.8 0.6 0.4" markrgb="1 1 1" random="0.01" />
    <material name="body" texture="body" texuniform="true" rgba="0.8 0.6 .4 1" />
    <texture name="grid" type="2d" builtin="checker" width="512" height="512" rgb1=".1 .2 .3" rgb2=".2 .3 .4" />
    <material name="grid" texture="grid" texrepeat="1 1" texuniform="true" reflectance=".2" />
  </asset>
  <worldbody>
    <geom name="floor" size="0 0 .05" type="plane" material="grid" condim="3" />
    <!-- <geom type="mesh" contype="0" conaffinity="0" group="1" density="0" mesh="body"/> -->
    <!-- <geom type="mesh" mesh="body" /> -->
    <light name="spotlight" mode="targetbodycom" target="torso" diffuse=".8 .8 .8" specular="0.3 0.3 0.3" pos="0 -6 4" cutoff="30" />
    <body name="torso" pos="0 0 1" quat="1.0 0.0 0.0 0.0">
      <inertial pos="0 0 0" quat="0.0 0.0 0.0 1.0" mass="3.3" diaginertia="0.111253 0.162030 0.152673" />
      <geom type="mesh" mesh="torso" />
      <freejoint name="floating base" />
      <light name="top" pos="0 0 2" mode="trackcom" />
      <body name="abduct_fr" pos="0.14775 -0.049 0" gravcomp="0">
        <inertial pos="0.055 -0.036 0" quat="0.564242 0.568689 0.421431 0.424993" mass="0.54" diaginertia="0.000577158 0.000443992 0.00036385" />
        <joint name="torso_to_abduct_fr_j" pos="0 0 0" axis="1 0 0" />
        <!-- <geom type="mesh" contype="0" conaffinity="0" group="1" density="0" mesh="abad"/> -->
        <geom type="mesh" mesh="abad" />
        <body name="thigh_fr" pos="0.055 -0.019 0" gravcomp="0">
          <inertial pos="0 0.016 -0.02" quat="0.899267 -0.00195739 -0.00366412 0.437381" mass="0.634" diaginertia="0.001498 0.001498 0.001498" />
          <joint name="abduct_fr_to_thigh_fr_j" pos="0 0 0" axis="0 -1 0" />
          <!-- <geom type="mesh" contype="0" conaffinity="0" group="1" density="0" mesh="thigh"/> -->
          <geom type="mesh" mesh="thigh" />
          <body name="shank_fr" pos="0 -0.049 -0.2085" gravcomp="0">
            <inertial pos="0 0 -0.061" quat="0.707107 0 0 0.707107" mass="0.064" diaginertia="0.000248 0.000245 6e-06" />
            <joint name="thigh_fr_to_knee_fr_j" pos="0 0 0" axis="0 -1 0" />
            <!-- <geom type="mesh" contype="0" conaffinity="0" group="1" density="0" mesh="shank"/> -->
            <geom type="mesh" mesh="shank" />
          </body>
        </body>
      </body>
      <body name="abduct_fl" pos="0.14775 0.049 0" gravcomp="0">
        <inertial pos="0.055 0.036 0" quat="0.564242 0.568689 0.421431 0.424993" mass="0.54" diaginertia="0.000577158 0.000443992 0.00036385" />
        <joint name="torso_to_abduct_fl_j" pos="0 0 0" axis="1 0 0" />
        <!-- <geom quat="3.26795e-07 1 0 0" type="mesh" contype="0" conaffinity="0" group="1" density="0" mesh="abad"/> -->
        <geom quat="3.26795e-07 1 0 0" type="mesh" mesh="abad" />
        <body name="thigh_fl" pos="0.055 0.019 0" gravcomp="0">
          <inertial pos="0 0.016 -0.02" quat="0.899267 -0.00195739 -0.00366412 0.437381" mass="0.634" diaginertia="0.001498 0.001498 0.001498" />
          <joint name="abduct_fl_to_thigh_fl_j" pos="0 0 0" axis="0 -1 0" />
          <!-- <geom quat="3.26795e-07 0 0 1" type="mesh" contype="0" conaffinity="0" group="1" density="0" mesh="thigh"/> -->
          <geom quat="3.26795e-07 0 0 1" type="mesh" mesh="thigh" />
          <body name="shank_fl" pos="0 0.049 -0.2085" gravcomp="0">
            <inertial pos="0 0 -0.061" quat="0.707107 0 0 0.707107" mass="0.064" diaginertia="0.000248 0.000245 6e-06" />
            <joint name="thigh_fl_to_knee_fl_j" pos="0 0 0" axis="0 -1 0" />
            <!-- <geom quat="3.26795e-07 0 0 1" type="mesh" contype="0" conaffinity="0" group="1" density="0" mesh="shank"/> -->
            <geom quat="3.26795e-07 0 0 1" type="mesh" mesh="shank" />
          </body>
        </body>
      </body>
      <body name="abduct_hr" pos="-0.14775 -0.049 0" quat="3.26795e-07 0 1 0" gravcomp="0">
        <inertial pos="0.055 -0.036 0" quat="0.564242 0.568689 0.421431 0.424993" mass="0.54" diaginertia="0.000577158 0.000443992 0.00036385" />
        <joint name="torso_to_abduct_hr_j" pos="0 0 0" axis="-1 0 0" />
        <!-- <geom type="mesh" contype="0" conaffinity="0" group="1" density="0" mesh="abad"/> -->
        <geom type="mesh" mesh="abad" />
        <body name="thigh_hr" pos="0.055 -0.019 0" quat="3.26795e-07 0 1 0" gravcomp="0">
          <inertial pos="0 0.016 -0.02" quat="0.899267 -0.00195739 -0.00366412 0.437381" mass="0.634" diaginertia="0.001498 0.001498 0.001498" />
          <joint name="abduct_hr_to_thigh_hr_j" pos="0 0 0" axis="0 -1 0" />
          <!-- <geom type="mesh" contype="0" conaffinity="0" group="1" density="0" mesh="thigh"/> -->
          <geom type="mesh" mesh="thigh" />
          <body name="shank_hr" pos="0 -0.049 -0.2085" gravcomp="0">
            <inertial pos="0 0 -0.061" quat="0.707107 0 0 0.707107" mass="0.064" diaginertia="0.000248 0.000245 6e-06" />
            <joint name="thigh_hr_to_knee_hr_j" pos="0 0 0" axis="0 -1 0" />
            <!-- <geom type="mesh" contype="0" conaffinity="0" group="1" density="0" mesh="shank"/> -->
            <geom type="mesh" mesh="shank" />
          </body>
        </body>
      </body>
      <body name="abduct_hl" pos="-0.14775 0.049 0" quat="3.26795e-07 0 1 0" gravcomp="0">
        <inertial pos="0.055 0.036 0" quat="0.564242 0.568689 0.421431 0.424993" mass="0.54" diaginertia="0.000577158 0.000443992 0.00036385" />
        <joint name="torso_to_abduct_hl_j" pos="0 0 0" axis="-1 0 0" />
        <!-- <geom quat="3.26795e-07 1 0 0" type="mesh" contype="0" conaffinity="0" group="1" density="0" mesh="abad"/> -->
        <geom quat="3.26795e-07 1 0 0" type="mesh" mesh="abad" />
        <body name="thigh_hl" pos="0.055 0.019 0" quat="3.26795e-07 0 1 0" gravcomp="0">
          <inertial pos="0 0.016 -0.02" quat="0.899267 -0.00195739 -0.00366412 0.437381" mass="0.634" diaginertia="0.001498 0.001498 0.001498" />
          <joint name="abduct_hl_to_thigh_hl_j" pos="0 0 0" axis="0 -1 0" />
          <!-- <geom quat="3.26795e-07 0 0 1" type="mesh" contype="0" conaffinity="0" group="1" density="0" mesh="thigh"/> -->
          <geom quat="3.26795e-07 0 0 1" type="mesh" mesh="thigh" />
          <body name="shank_hl" pos="0 0.049 -0.2085" gravcomp="0">
            <inertial pos="0 0 -0.061" quat="0.707107 0 0 0.707107" mass="0.064" diaginertia="0.000248 0.000245 6e-06" />
            <joint name="thigh_hl_to_knee_hl_j" pos="0 0 0" axis="0 -1 0" />
            <!-- <geom quat="3.26795e-07 0 0 1" type="mesh" contype="0" conaffinity="0" group="1" density="0" mesh="shank"/> -->
            <geom quat="3.26795e-07 0 0 1" type="mesh" mesh="shank" />
          </body>
        </body>
      </body>
    </body>
  </worldbody>

  <actuator>
    <position name="abad_fl" joint="torso_to_abduct_fl_j" kp="1" />
    <position name="hip_flext_fl" joint="abduct_fl_to_thigh_fl_j" kp="1" />
    <position name="knee_flext_fl" joint="thigh_fl_to_knee_fl_j" kp="1" />
    <position name="abad_fr" joint="torso_to_abduct_fr_j" kp="1" />
    <position name="hip_flext_fr" joint="abduct_fr_to_thigh_fr_j" kp="1" />
    <position name="knee_flext_fr" joint="thigh_fr_to_knee_fr_j" kp="1" />
    <position name="abad_hl" joint="torso_to_abduct_hl_j" kp="1" />
    <position name="hip_flext_hl" joint="abduct_hl_to_thigh_hl_j" kp="1" />
    <position name="knee_flext_hl" joint="thigh_hl_to_knee_hl_j" kp="1" />
    <position name="abad_hr" joint="torso_to_abduct_hr_j" kp="1" />
    <position name="hip_flext_hr" joint="abduct_hr_to_thigh_hr_j" kp="1" />
    <position name="knee_flext_hr" joint="thigh_hr_to_knee_hr_j" kp="1" />
  </actuator>
</mujoco>